Workbook

Sheet Main
A1: Today | B1: Copy this doc and follow the link below for instructions. | D1: =SUMIF($A$5:$A$100,">0",D$5:D$100) -> 35 | E1: =SUMIF($A$5:$A$100,">0",E$5:E$100) -> 39 | F1: =SUMIF($A$5:$A$100,">0",F$5:F$100) -> 19 | I1: 1 | J1: =IF(I3>=$F$103,0, VLOOKUP(I2,$I$102:$K$108,3,FALSE)) -> 3 | K1: =IF(J3>=$F$103,0, VLOOKUP(J2,$I$102:$K$108,3,FALSE)) -> 1 | L1: =IF(K3>=$F$103,0, VLOOKUP(K2,$I$102:$K$108,3,FALSE)) -> 1 | M1: =IF(L3>=$F$103,0, VLOOKUP(L2,$I$102:$K$108,3,FALSE)) -> 1 | N1: =IF(M3>=$F$103,0, VLOOKUP(M2,$I$102:$K$108,3,FALSE)) -> 1 | O1: =IF(N3>=$F$103,0, VLOOKUP(N2,$I$102:$K$108,3,FALSE)) -> 3 | P1: =IF(O3>=$F$103,0, VLOOKUP(O2,$I$102:$K$108,3,FALSE)) -> 1 | Q1: =IF(P3>=$F$103,0, VLOOKUP(P2,$I$102:$K$108,3,FALSE)) -> 1 | ... Z1: =IF(Y3>=$F$103,0, VLOOKUP(Y2,$I$102:$K$108,3,FALSE)) -> 0 | AB1: This doc is: http://book.prototools.net/r/BDC_Instructions
A2: 44908 | B2: http://book.prototools.net/r/BDC_Instructions | D2: Hours | E2: Hours | F2: Hours | I2: =CHOOSE(WEEKDAY(I3),"Sun","Mon","Tue","Wed","Thu","Fri","Sat") -> Fri | J2: =CHOOSE(WEEKDAY(J3),"Sun","Mon","Tue","Wed","Thu","Fri","Sat") -> Mon | K2: =CHOOSE(WEEKDAY(K3),"Sun","Mon","Tue","Wed","Thu","Fri","Sat") -> Tue | L2: =CHOOSE(WEEKDAY(L3),"Sun","Mon","Tue","Wed","Thu","Fri","Sat") -> Wed | M2: =CHOOSE(WEEKDAY(M3),"Sun","Mon","Tue","Wed","Thu","Fri","Sat") -> Thu | N2: =CHOOSE(WEEKDAY(N3),"Sun","Mon","Tue","Wed","Thu","Fri","Sat") -> Fri | O2: =CHOOSE(WEEKDAY(O3),"Sun","Mon","Tue","Wed","Thu","Fri","Sat") -> Mon | P2: =CHOOSE(WEEKDAY(P3),"Sun","Mon","Tue","Wed","Thu","Fri","Sat") -> Tue | ... Z2: =CHOOSE(WEEKDAY(Z3),"Sun","Mon","Tue","Wed","Thu","Fri","Sat") -> Fri
A3: Rank | B3: Task | C3: Assn | D3: Est. | E3: Total | F3: Rem. | I3: =F102 -> 44568 | J3: =I3+J1 -> 44571 | K3: =J3+K1 -> 44572 | L3: =K3+L1 -> 44573 | M3: =L3+M1 -> 44574 | N3: =M3+N1 -> 44575 | O3: =N3+O1 -> 44578 | P3: =O3+P1 -> 44579 | Q3: =P3+Q1 -> 44580 | ... Z3: =Y3+Z1 -> 44582 | AB3: Detailed Information
A4: Task Assignments
B5: -- Mechanics Physics -- | E5: =D5 -> 0 | F5: =Z5 -> 0 | H5: =E5 -> 0 | I5: =H5 -> 0 | J5: =I5 -> 0 | K5: =J5 -> 0 | L5: =K5 -> 0 | M5: =L5 -> 0 | N5: =M5 -> 0 | O5: =N5 -> 0 | P5: =O5 -> 0 | ... Z5: =Y5 -> 0
A6: 1 | B6: Jumping | C6: A | D6: 4 | E6: 6 | F6: =Z6 -> 0 | H6: =E6 -> 6 | I6: 3 | J6: 6 | K6: 2 | L6: 1 | M6: 0 | N6: =M6 -> 0 | O6: =N6 -> 0 | P6: =O6 -> 0 | Q6: =P6 -> 0 | R6: =Q6 -> 0 | S6: =R6 -> 0 | T6: =S6 -> 0 | U6: =T6 -> 0 | ... Z6: =Y6 -> 0
A7: 1 | B7: – Help with Jumping | C7: P | D7: 0 | E7: 2 | F7: =Z7 -> 0 | H7: =E7 -> 2 | I7: =H7 -> 2 | J7: =I7 -> 2 | K7: 0 | L7: =K7 -> 0 | M7: =L7 -> 0 | N7: =M7 -> 0 | O7: =N7 -> 0 | P7: =O7 -> 0 | Q7: =P7 -> 0 | R7: =Q7 -> 0 | S7: =R7 -> 0 | ... Z7: =Y7 -> 0
A8: 1 | B8: Force | C8: A | D8: 2 | E8: 1 | F8: =Z8 -> 0 | H8: =E8 -> 1 | I8: =H8 -> 1 | J8: =I8 -> 1 | K8: =J8 -> 1 | L8: 0 | M8: =L8 -> 0 | N8: =M8 -> 0 | O8: =N8 -> 0 | P8: =O8 -> 0 | Q8: =P8 -> 0 | R8: =Q8 -> 0 | S8: =R8 -> 0 | T8: =S8 -> 0 | ... Z8: =Y8 -> 0
A9: 1 | B9: Grabbing | C9: C | D9: 2 | E9: =D9 -> 2 | F9: =Z9 -> 2 | H9: =E9 -> 2 | I9: =H9 -> 2 | J9: =I9 -> 2 | K9: =J9 -> 2 | L9: =K9 -> 2 | M9: =L9 -> 2 | N9: =M9 -> 2 | O9: =N9 -> 2 | P9: =O9 -> 2 | ... Z9: =Y9 -> 2
A10: 1 | B10: Gravity | C10: A | D10: 2 | E10: =D10 -> 2 | F10: =Z10 -> 2 | H10: =E10 -> 2 | I10: =H10 -> 2 | J10: =I10 -> 2 | K10: =J10 -> 2 | L10: =K10 -> 2 | M10: =L10 -> 2 | N10: =M10 -> 2 | O10: =N10 -> 2 | P10: =O10 -> 2 | ... Z10: =Y10 -> 2
A11: 1 | B11: Collision Implementation | C11: P | D11: 4 | E11: 4 | F11: =Z11 -> 2 | H11: =E11 -> 4 | I11: 3 | J11: 2 | K11: =J11 -> 2 | L11: =K11 -> 2 | M11: =L11 -> 2 | N11: =M11 -> 2 | O11: =N11 -> 2 | P11: =O11 -> 2 | Q11: =P11 -> 2 | R11: =Q11 -> 2 | ... Z11: =Y11 -> 2
E12: =D12 -> 0 | F12: =Z12 -> 0 | H12: =E12 -> 0 | I12: =H12 -> 0 | J12: =I12 -> 0 | K12: =J12 -> 0 | L12: =K12 -> 0 | M12: =L12 -> 0 | N12: =M12 -> 0 | O12: =N12 -> 0 | P12: =O12 -> 0 | ... Z12: =Y12 -> 0
B13: -- Camera -- | E13: =D13 -> 0 | F13: =Z13 -> 0 | H13: =E13 -> 0 | I13: =H13 -> 0 | J13: =I13 -> 0 | K13: =J13 -> 0 | L13: =K13 -> 0 | M13: =L13 -> 0 | N13: =M13 -> 0 | O13: =N13 -> 0 | P13: =O13 -> 0 | ... Z13: =Y13 -> 0
A14: 1 | B14: Delayed Jump when bigger | C14: A | D14: 2 | E14: =D14 -> 2 | F14: =Z14 -> 0 | H14: =E14 -> 2 | I14: =H14 -> 2 | J14: 0 | K14: =J14 -> 0 | L14: =K14 -> 0 | M14: =L14 -> 0 | N14: =M14 -> 0 | O14: =N14 -> 0 | P14: =O14 -> 0 | Q14: =P14 -> 0 | R14: =Q14 -> 0 | ... Z14: =Y14 -> 0
A15: 1 | B15: Zoom in when intense | C15: P | D15: 1 | E15: =D15 -> 1 | F15: =Z15 -> 1 | H15: =E15 -> 1 | I15: =H15 -> 1 | J15: =I15 -> 1 | K15: =J15 -> 1 | L15: =K15 -> 1 | M15: =L15 -> 1 | N15: =M15 -> 1 | O15: =N15 -> 1 | P15: =O15 -> 1 | ... Z15: =Y15 -> 1
E16: =D16 -> 0 | F16: =Z16 -> 0 | H16: =E16 -> 0 | I16: =H16 -> 0 | J16: =I16 -> 0 | K16: =J16 -> 0 | L16: =K16 -> 0 | M16: =L16 -> 0 | N16: =M16 -> 0 | O16: =N16 -> 0 | P16: =O16 -> 0 | ... Z16: =Y16 -> 0
B17: -- Art -- | E17: =D17 -> 0 | F17: =Z17 -> 0 | H17: =E17 -> 0 | I17: =H17 -> 0 | J17: =I17 -> 0 | K17: =J17 -> 0 | L17: =K17 -> 0 | M17: =L17 -> 0 | N17: =M17 -> 0 | O17: =N17 -> 0 | P17: =O17 -> 0 | ... Z17: =Y17 -> 0
A18: 1 | B18: Player Models | C18: C | D18: 4 | E18: =D18 -> 4 | F18: =Z18 -> 3 | H18: =E18 -> 4 | I18: =H18 -> 4 | J18: =I18 -> 4 | K18: =J18 -> 4 | L18: 3 | M18: =L18 -> 3 | N18: =M18 -> 3 | O18: =N18 -> 3 | P18: =O18 -> 3 | Q18: =P18 -> 3 | R18: =Q18 -> 3 | S18: =R18 -> 3 | T18: =S18 -> 3 | ... Z18: =Y18 -> 3
A19: 2 | B19: multiple Clothes cosmetics for player | C19: P | D19: 2 | E19: =D19 -> 2 | F19: =Z19 -> 1 | H19: =E19 -> 2 | I19: =H19 -> 2 | J19: =I19 -> 2 | K19: 1 | L19: =K19 -> 1 | M19: =L19 -> 1 | N19: =M19 -> 1 | O19: =N19 -> 1 | P19: =O19 -> 1 | Q19: =P19 -> 1 | R19: =Q19 -> 1 | S19: =R19 -> 1 | ... Z19: =Y19 -> 1
A20: 3 | B20: custom gear | C20: C | D20: 2 | E20: =D20 -> 2 | F20: =Z20 -> 2 | H20: =E20 -> 2 | I20: =H20 -> 2 | J20: =I20 -> 2 | K20: =J20 -> 2 | L20: =K20 -> 2 | M20: =L20 -> 2 | N20: =M20 -> 2 | O20: =N20 -> 2 | P20: =O20 -> 2 | ... Z20: =Y20 -> 2
E21: =D21 -> 0 | F21: =Z21 -> 0 | H21: =E21 -> 0 | I21: =H21 -> 0 | J21: =I21 -> 0 | K21: =J21 -> 0 | L21: =K21 -> 0 | M21: =L21 -> 0 | N21: =M21 -> 0 | O21: =N21 -> 0 | P21: =O21 -> 0 | ... Z21: =Y21 -> 0
B22: -- Gameplay & Scoring -- | E22: =D22 -> 0 | F22: =Z22 -> 0 | H22: =E22 -> 0 | I22: =H22 -> 0 | J22: =I22 -> 0 | K22: =J22 -> 0 | L22: =K22 -> 0 | M22: =L22 -> 0 | N22: =M22 -> 0 | O22: =N22 -> 0 | P22: =O22 -> 0 | ... Z22: =Y22 -> 0
A23: 1 | B23: lose XP when Fail | C23: P | D23: 1 | E23: =D23 -> 1 | F23: =Z23 -> 1 | H23: =E23 -> 1 | I23: =H23 -> 1 | J23: =I23 -> 1 | K23: =J23 -> 1 | L23: =K23 -> 1 | M23: =L23 -> 1 | N23: =M23 -> 1 | O23: =N23 -> 1 | P23: =O23 -> 1 | ... Z23: =Y23 -> 1
A24: 3 | B24: gain XP when Succses | C24: A | D24: 1 | E24: 2 | F24: =Z24 -> 0 | H24: =E24 -> 2 | I24: =H24 -> 2 | J24: =I24 -> 2 | K24: =J24 -> 2 | L24: =K24 -> 2 | M24: 0 | N24: =M24 -> 0 | O24: =N24 -> 0 | P24: =O24 -> 0 | Q24: =P24 -> 0 | R24: =Q24 -> 0 | S24: =R24 -> 0 | T24: =S24 -> 0 | U24: =T24 -> 0 | ... Z24: =Y24 -> 0
A25: 2 | B25: limb System | C25: C | D25: 2 | E25: =D25 -> 2 | F25: =Z25 -> 1 | H25: =E25 -> 2 | I25: =H25 -> 2 | J25: =I25 -> 2 | K25: =J25 -> 2 | L25: =K25 -> 2 | M25: 1 | N25: =M25 -> 1 | O25: =N25 -> 1 | P25: =O25 -> 1 | Q25: =P25 -> 1 | R25: =Q25 -> 1 | S25: =R25 -> 1 | T25: =S25 -> 1 | U25: =T25 -> 1 | ... Z25: =Y25 -> 1
A26: 2 | B26: Time Limit | C26: C | D26: 1 | E26: =D26 -> 1 | F26: =Z26 -> 1 | H26: =E26 -> 1 | I26: =H26 -> 1 | J26: =I26 -> 1 | K26: =J26 -> 1 | L26: =K26 -> 1 | M26: =L26 -> 1 | N26: =M26 -> 1 | O26: =N26 -> 1 | P26: =O26 -> 1 | ... Z26: =Y26 -> 1
E27: =D27 -> 0 | F27: =Z27 -> 0 | H27: =E27 -> 0 | I27: =H27 -> 0 | J27: =I27 -> 0 | K27: =J27 -> 0 | L27: =K27 -> 0 | M27: =L27 -> 0 | N27: =M27 -> 0 | O27: =N27 -> 0 | P27: =O27 -> 0 | ... Z27: =Y27 -> 0
B28: -- AI Behavior -- | E28: =D28 -> 0 | F28: =Z28 -> 0 | H28: =E28 -> 0 | I28: =H28 -> 0 | J28: =I28 -> 0 | K28: =J28 -> 0 | L28: =K28 -> 0 | M28: =L28 -> 0 | N28: =M28 -> 0 | O28: =N28 -> 0 | P28: =O28 -> 0 | ... Z28: =Y28 -> 0
A29: 4 | B29: AI Shopkeeper | C29: P | D29: 5 | E29: =D29 -> 5 | F29: =Z29 -> 3 | H29: =E29 -> 5 | I29: =H29 -> 5 | J29: 3 | K29: 3 | L29: =K29 -> 3 | M29: =L29 -> 3 | N29: =M29 -> 3 | O29: =N29 -> 3 | P29: =O29 -> 3 | Q29: =P29 -> 3 | R29: =Q29 -> 3 | S29: =R29 -> 3 | ... Z29: =Y29 -> 3
E30: =D30 -> 0 | F30: =Z30 -> 0 | H30: =E30 -> 0 | I30: =H30 -> 0 | J30: =I30 -> 0 | K30: =J30 -> 0 | L30: =K30 -> 0 | M30: =L30 -> 0 | N30: =M30 -> 0 | O30: =N30 -> 0 | P30: =O30 -> 0 | ... Z30: =Y30 -> 0
E31: =D31 -> 0 | F31: =Z31 -> 0 | H31: =E31 -> 0 | I31: =H31 -> 0 | J31: =I31 -> 0 | K31: =J31 -> 0 | L31: =K31 -> 0 | M31: =L31 -> 0 | N31: =M31 -> 0 | O31: =N31 -> 0 | P31: =O31 -> 0 | ... Z31: =Y31 -> 0
E32: =D32 -> 0 | F32: =Z32 -> 0 | H32: =E32 -> 0 | I32: =H32 -> 0 | J32: =I32 -> 0 | K32: =J32 -> 0 | L32: =K32 -> 0 | M32: =L32 -> 0 | N32: =M32 -> 0 | O32: =N32 -> 0 | P32: =O32 -> 0 | ... Z32: =Y32 -> 0
E33: =D33 -> 0 | F33: =Z33 -> 0 | H33: =E33 -> 0 | I33: =H33 -> 0 | J33: =I33 -> 0 | K33: =J33 -> 0 | L33: =K33 -> 0 | M33: =L33 -> 0 | N33: =M33 -> 0 | O33: =N33 -> 0 | P33: =O33 -> 0 | ... Z33: =Y33 -> 0
E34: =D34 -> 0 | F34: =Z34 -> 0 | H34: =E34 -> 0 | I34: =H34 -> 0 | J34: =I34 -> 0 | K34: =J34 -> 0 | L34: =K34 -> 0 | M34: =L34 -> 0 | N34: =M34 -> 0 | O34: =N34 -> 0 | P34: =O34 -> 0 | ... Z34: =Y34 -> 0
E35: =D35 -> 0 | F35: =Z35 -> 0 | H35: =E35 -> 0 | I35: =H35 -> 0 | J35: =I35 -> 0 | K35: =J35 -> 0 | L35: =K35 -> 0 | M35: =L35 -> 0 | N35: =M35 -> 0 | O35: =N35 -> 0 | P35: =O35 -> 0 | ... Z35: =Y35 -> 0
E36: =D36 -> 0 | F36: =Z36 -> 0 | H36: =E36 -> 0 | I36: =H36 -> 0 | J36: =I36 -> 0 | K36: =J36 -> 0 | L36: =K36 -> 0 | M36: =L36 -> 0 | N36: =M36 -> 0 | O36: =N36 -> 0 | P36: =O36 -> 0 | ... Z36: =Y36 -> 0
E37: =D37 -> 0 | F37: =Z37 -> 0 | H37: =E37 -> 0 | I37: =H37 -> 0 | J37: =I37 -> 0 | K37: =J37 -> 0 | L37: =K37 -> 0 | M37: =L37 -> 0 | N37: =M37 -> 0 | O37: =N37 -> 0 | P37: =O37 -> 0 | ... Z37: =Y37 -> 0
E38: =D38 -> 0 | F38: =Z38 -> 0 | H38: =E38 -> 0 | I38: =H38 -> 0 | J38: =I38 -> 0 | K38: =J38 -> 0 | L38: =K38 -> 0 | M38: =L38 -> 0 | N38: =M38 -> 0 | O38: =N38 -> 0 | P38: =O38 -> 0 | ... Z38: =Y38 -> 0
E39: =D39 -> 0 | F39: =Z39 -> 0 | H39: =E39 -> 0 | I39: =H39 -> 0 | J39: =I39 -> 0 | K39: =J39 -> 0 | L39: =K39 -> 0 | M39: =L39 -> 0 | N39: =M39 -> 0 | O39: =N39 -> 0 | P39: =O39 -> 0 | ... Z39: =Y39 -> 0
E40: =D40 -> 0 | F40: =Z40 -> 0 | H40: =E40 -> 0 | I40: =H40 -> 0 | J40: =I40 -> 0 | K40: =J40 -> 0 | L40: =K40 -> 0 | M40: =L40 -> 0 | N40: =M40 -> 0 | O40: =N40 -> 0 | P40: =O40 -> 0 | ... Z40: =Y40 -> 0
...

Sheet Daily Scrum
A1: =Main!A2 -> 44908 | C1: Team Members | J1: Daily
A2: Dates | C2: =Main!B102 -> Adam | D2: =Main!B103 -> Padraic | E2: =Main!B104 -> Chris | F2: =Main!B105 -> 0 | G2: =Main!B106 -> 0 | H2: =Main!B129 -> 0 | J2: Template | K2: Workday
A3: =Main!I3 -> 44568 | B3: =CHOOSE(WEEKDAY(A3),"Sun","Mon","Tue","Wed","Thu","Fri","Sat") -> Fri | C3: Yesterday: Project Kickoff Today: Acceleration Help: – Nothing now | D3: Yesterday: Project Kickoff Today: Collisions Help: – | E3: Yesterday: Project Kickoff Today: Out of town until 12/13 Help: – | F3: Yesterday: Project Kickoff Today: No time today Help: – | J3: Y: – T: – H: – | K3: =VLOOKUP($B3,Main!$I$102:$J$108,2,FALSE) -> 1
A4: =A3+1 -> 44569 | B4: =CHOOSE(WEEKDAY(A4),"Sun","Mon","Tue","Wed","Thu","Fri","Sat") -> Sat | C4: Y: Tried something for the torque curve that didn't work. That's two hours I won't get back. :/ T: More work on Acceleration. H: I now feel further from the solution for acceleration. I could use some help. | D4: Y: Some work on collisions T: More collisions H: – | E4: Y: – T: Still out of town. Call if you need anything (555) 867-5309. H: – | F4: Y: – T: Follow cam (delayed car angling tracking thing) H: – | K4: =VLOOKUP($B4,Main!$I$102:$J$108,2,FALSE) -> 0
A5: =A4+1 -> 44570 | B5: =CHOOSE(WEEKDAY(A5),"Sun","Mon","Tue","Wed","Thu","Fri","Sat") -> Sun | C5: Y: Realized the torque curve of Acceleration is a bigger task than I thought. T: More Acceleration work. H: – | D5: Y: Collisions halfway done now T: I have time to help Archon H: – | E5: Y: – T: – H: – | K5: =VLOOKUP($B5,Main!$I$102:$J$108,2,FALSE) -> 0
A6: =A5+1 -> 44571 | B6: =CHOOSE(WEEKDAY(A6),"Sun","Mon","Tue","Wed","Thu","Fri","Sat") -> Mon | K6: =VLOOKUP($B6,Main!$I$102:$J$108,2,FALSE) -> 1
A7: =A6+1 -> 44572 | B7: =CHOOSE(WEEKDAY(A7),"Sun","Mon","Tue","Wed","Thu","Fri","Sat") -> Tue | K7: =VLOOKUP($B7,Main!$I$102:$J$108,2,FALSE) -> 1
A8: =A7+1 -> 44573 | B8: =CHOOSE(WEEKDAY(A8),"Sun","Mon","Tue","Wed","Thu","Fri","Sat") -> Wed | C8: Y: (Fri) Got help from Hannah with acceleration. Now much closer to done! (Sun) Also worked an hour on acceleration this weekend. I need a break. T: – H: – | D8: Y: Didn't do any of my work because Acceleration issues took all my time. T: Out for the next three days H: – | E8: Y: – T: Back tomorrow. H: – | K8: =VLOOKUP($B8,Main!$I$102:$J$108,2,FALSE) -> 1
A9: =A8+1 -> 44574 | B9: =CHOOSE(WEEKDAY(A9),"Sun","Mon","Tue","Wed","Thu","Fri","Sat") -> Thu | C9: Y: Worked on Speed. T: Back to accel; hopefully finishing. H: – | E9: Y: – T: Finally back! Working on Point System. H: If someone could help get me back up to speed, I'd appreciate it. | F9: Y: – T: Risky driving system H: – | K9: =VLOOKUP($B9,Main!$I$102:$J$108,2,FALSE) -> 1
A10: =A9+1 -> 44575 | B10: =CHOOSE(WEEKDAY(A10),"Sun","Mon","Tue","Wed","Thu","Fri","Sat") -> Fri | K10: =VLOOKUP($B10,Main!$I$102:$J$108,2,FALSE) -> 1
A11: =A10+1 -> 44576 | B11: =CHOOSE(WEEKDAY(A11),"Sun","Mon","Tue","Wed","Thu","Fri","Sat") -> Sat | K11: =VLOOKUP($B11,Main!$I$102:$J$108,2,FALSE) -> 0
A12: =A11+1 -> 44577 | B12: =CHOOSE(WEEKDAY(A12),"Sun","Mon","Tue","Wed","Thu","Fri","Sat") -> Sun | K12: =VLOOKUP($B12,Main!$I$102:$J$108,2,FALSE) -> 0
A13: =A12+1 -> 44578 | B13: =CHOOSE(WEEKDAY(A13),"Sun","Mon","Tue","Wed","Thu","Fri","Sat") -> Mon | K13: =VLOOKUP($B13,Main!$I$102:$J$108,2,FALSE) -> 1
A14: =A13+1 -> 44579 | B14: =CHOOSE(WEEKDAY(A14),"Sun","Mon","Tue","Wed","Thu","Fri","Sat") -> Tue | K14: =VLOOKUP($B14,Main!$I$102:$J$108,2,FALSE) -> 1
A15: =A14+1 -> 44580 | B15: =CHOOSE(WEEKDAY(A15),"Sun","Mon","Tue","Wed","Thu","Fri","Sat") -> Wed | K15: =VLOOKUP($B15,Main!$I$102:$J$108,2,FALSE) -> 1
A16: =A15+1 -> 44581 | B16: =CHOOSE(WEEKDAY(A16),"Sun","Mon","Tue","Wed","Thu","Fri","Sat") -> Thu | K16: =VLOOKUP($B16,Main!$I$102:$J$108,2,FALSE) -> 1
A17: =A16+1 -> 44582 | B17: =CHOOSE(WEEKDAY(A17),"Sun","Mon","Tue","Wed","Thu","Fri","Sat") -> Fri | K17: =VLOOKUP($B17,Main!$I$102:$J$108,2,FALSE) -> 1
A18: =A17+1 -> 44583 | B18: =CHOOSE(WEEKDAY(A18),"Sun","Mon","Tue","Wed","Thu","Fri","Sat") -> Sat | K18: =VLOOKUP($B18,Main!$I$102:$J$108,2,FALSE) -> 0
A19: =A18+1 -> 44584 | B19: =CHOOSE(WEEKDAY(A19),"Sun","Mon","Tue","Wed","Thu","Fri","Sat") -> Sun | K19: =VLOOKUP($B19,Main!$I$102:$J$108,2,FALSE) -> 0
A20: =A19+1 -> 44585 | B20: =CHOOSE(WEEKDAY(A20),"Sun","Mon","Tue","Wed","Thu","Fri","Sat") -> Mon | K20: =VLOOKUP($B20,Main!$I$102:$J$108,2,FALSE) -> 1
A21: =A20+1 -> 44586 | B21: =CHOOSE(WEEKDAY(A21),"Sun","Mon","Tue","Wed","Thu","Fri","Sat") -> Tue | K21: =VLOOKUP($B21,Main!$I$102:$J$108,2,FALSE) -> 1
... A24: =A23+1 -> 44589 | B24: =CHOOSE(WEEKDAY(A24),"Sun","Mon","Tue","Wed","Thu","Fri","Sat") -> Fri | K24: =VLOOKUP($B24,Main!$I$102:$J$108,2,FALSE) -> 1
